2017-02-17 12:27:48 [scrapy] ERROR: Error downloading <GET https://www.atagar.com/robots.txt>: <urlopen error [WinError 10061] No connection could be made because the target machine actively refused it>
Traceback (most recent call last):
  File "D:\Program Files\Anaconda3\envs\scrapy_test\lib\urllib\request.py", line 1318, in do_open
    encode_chunked=req.has_header('Transfer-encoding'))
  File "D:\Program Files\Anaconda3\envs\scrapy_test\lib\http\client.py", line 1239, in request
    self._send_request(method, url, body, headers, encode_chunked)
  File "D:\Program Files\Anaconda3\envs\scrapy_test\lib\http\client.py", line 1285, in _send_request
    self.endheaders(body, encode_chunked=encode_chunked)
  File "D:\Program Files\Anaconda3\envs\scrapy_test\lib\http\client.py", line 1234, in endheaders
    self._send_output(message_body, encode_chunked=encode_chunked)
  File "D:\Program Files\Anaconda3\envs\scrapy_test\lib\http\client.py", line 1026, in _send_output
    self.send(msg)
  File "D:\Program Files\Anaconda3\envs\scrapy_test\lib\http\client.py", line 964, in send
    self.connect()
  File "D:\Program Files\Anaconda3\envs\scrapy_test\lib\http\client.py", line 936, in connect
    (self.host,self.port), self.timeout, self.source_address)
  File "D:\Program Files\Anaconda3\envs\scrapy_test\lib\socket.py", line 722, in create_connection
    raise err
  File "D:\Program Files\Anaconda3\envs\scrapy_test\lib\socket.py", line 713, in create_connection
    sock.connect(sa)
ConnectionRefusedError: [WinError 10061] No connection could be made because the target machine actively refused it

During handling of the above exception, another exception occurred:

Traceback (most recent call last):
  File "D:\Program Files\Anaconda3\envs\scrapy_test\lib\site-packages\twisted\internet\defer.py", line 1299, in _inlineCallbacks
    result = g.send(result)
  File "D:\Program Files\Anaconda3\envs\scrapy_test\lib\site-packages\scrapy\core\downloader\middleware.py", line 37, in process_request
    response = yield method(request=request, spider=spider)
  File "C:\Users\djj\Desktop\upwork\ebook\ebook\middlewares\JsMiddleware.py", line 44, in process_request
    self.driver.get(request.url)
  File "D:\Program Files\Anaconda3\envs\scrapy_test\lib\site-packages\selenium\webdriver\remote\webdriver.py", line 248, in get
    self.execute(Command.GET, {'url': url})
  File "D:\Program Files\Anaconda3\envs\scrapy_test\lib\site-packages\selenium\webdriver\remote\webdriver.py", line 234, in execute
    response = self.command_executor.execute(driver_command, params)
  File "D:\Program Files\Anaconda3\envs\scrapy_test\lib\site-packages\selenium\webdriver\remote\remote_connection.py", line 408, in execute
    return self._request(command_info[0], url, body=data)
  File "D:\Program Files\Anaconda3\envs\scrapy_test\lib\site-packages\selenium\webdriver\remote\remote_connection.py", line 478, in _request
    resp = opener.open(request, timeout=self._timeout)
  File "D:\Program Files\Anaconda3\envs\scrapy_test\lib\urllib\request.py", line 526, in open
    response = self._open(req, data)
  File "D:\Program Files\Anaconda3\envs\scrapy_test\lib\urllib\request.py", line 544, in _open
    '_open', req)
  File "D:\Program Files\Anaconda3\envs\scrapy_test\lib\urllib\request.py", line 504, in _call_chain
    result = func(*args)
  File "D:\Program Files\Anaconda3\envs\scrapy_test\lib\urllib\request.py", line 1346, in http_open
    return self.do_open(http.client.HTTPConnection, req)
  File "D:\Program Files\Anaconda3\envs\scrapy_test\lib\urllib\request.py", line 1320, in do_open
    raise URLError(err)
urllib.error.URLError: <urlopen error [WinError 10061] No connection could be made because the target machine actively refused it>
2017-02-17 12:27:59 [scrapy] ERROR: Spider error processing <GET http://ip.42.pl/raw> (referer: None)
Traceback (most recent call last):
  File "D:\Program Files\Anaconda3\envs\scrapy_test\lib\site-packages\twisted\internet\defer.py", line 651, in _runCallbacks
    current.result = callback(current.result, *args, **kw)
  File "C:\Users\djj\Desktop\upwork\ebook\ebook\spiders\proxy_test_spider.py", line 10, in parse
    print(response.body.encode('utf8'))
AttributeError: 'bytes' object has no attribute 'encode'
2017-02-17 12:27:59 [scrapy] ERROR: Error downloading <GET https://www.atagar.com/echo.php>
Traceback (most recent call last):
  File "D:\Program Files\Anaconda3\envs\scrapy_test\lib\urllib\request.py", line 1318, in do_open
    encode_chunked=req.has_header('Transfer-encoding'))
  File "D:\Program Files\Anaconda3\envs\scrapy_test\lib\http\client.py", line 1239, in request
    self._send_request(method, url, body, headers, encode_chunked)
  File "D:\Program Files\Anaconda3\envs\scrapy_test\lib\http\client.py", line 1285, in _send_request
    self.endheaders(body, encode_chunked=encode_chunked)
  File "D:\Program Files\Anaconda3\envs\scrapy_test\lib\http\client.py", line 1234, in endheaders
    self._send_output(message_body, encode_chunked=encode_chunked)
  File "D:\Program Files\Anaconda3\envs\scrapy_test\lib\http\client.py", line 1026, in _send_output
    self.send(msg)
  File "D:\Program Files\Anaconda3\envs\scrapy_test\lib\http\client.py", line 964, in send
    self.connect()
  File "D:\Program Files\Anaconda3\envs\scrapy_test\lib\http\client.py", line 936, in connect
    (self.host,self.port), self.timeout, self.source_address)
  File "D:\Program Files\Anaconda3\envs\scrapy_test\lib\socket.py", line 722, in create_connection
    raise err
  File "D:\Program Files\Anaconda3\envs\scrapy_test\lib\socket.py", line 713, in create_connection
    sock.connect(sa)
ConnectionRefusedError: [WinError 10061] No connection could be made because the target machine actively refused it

During handling of the above exception, another exception occurred:

Traceback (most recent call last):
  File "D:\Program Files\Anaconda3\envs\scrapy_test\lib\site-packages\twisted\internet\defer.py", line 1299, in _inlineCallbacks
    result = g.send(result)
  File "D:\Program Files\Anaconda3\envs\scrapy_test\lib\site-packages\scrapy\core\downloader\middleware.py", line 37, in process_request
    response = yield method(request=request, spider=spider)
  File "C:\Users\djj\Desktop\upwork\ebook\ebook\middlewares\JsMiddleware.py", line 44, in process_request
    self.driver.get(request.url)
  File "D:\Program Files\Anaconda3\envs\scrapy_test\lib\site-packages\selenium\webdriver\remote\webdriver.py", line 248, in get
    self.execute(Command.GET, {'url': url})
  File "D:\Program Files\Anaconda3\envs\scrapy_test\lib\site-packages\selenium\webdriver\remote\webdriver.py", line 234, in execute
    response = self.command_executor.execute(driver_command, params)
  File "D:\Program Files\Anaconda3\envs\scrapy_test\lib\site-packages\selenium\webdriver\remote\remote_connection.py", line 408, in execute
    return self._request(command_info[0], url, body=data)
  File "D:\Program Files\Anaconda3\envs\scrapy_test\lib\site-packages\selenium\webdriver\remote\remote_connection.py", line 478, in _request
    resp = opener.open(request, timeout=self._timeout)
  File "D:\Program Files\Anaconda3\envs\scrapy_test\lib\urllib\request.py", line 526, in open
    response = self._open(req, data)
  File "D:\Program Files\Anaconda3\envs\scrapy_test\lib\urllib\request.py", line 544, in _open
    '_open', req)
  File "D:\Program Files\Anaconda3\envs\scrapy_test\lib\urllib\request.py", line 504, in _call_chain
    result = func(*args)
  File "D:\Program Files\Anaconda3\envs\scrapy_test\lib\urllib\request.py", line 1346, in http_open
    return self.do_open(http.client.HTTPConnection, req)
  File "D:\Program Files\Anaconda3\envs\scrapy_test\lib\urllib\request.py", line 1320, in do_open
    raise URLError(err)
urllib.error.URLError: <urlopen error [WinError 10061] No connection could be made because the target machine actively refused it>
2017-02-17 12:28:07 [scrapy] ERROR: Spider error processing <GET http://ip.42.pl/raw> (referer: None)
Traceback (most recent call last):
  File "D:\Program Files\Anaconda3\envs\scrapy_test\lib\site-packages\twisted\internet\defer.py", line 651, in _runCallbacks
    current.result = callback(current.result, *args, **kw)
  File "C:\Users\djj\Desktop\upwork\ebook\ebook\spiders\proxy_test_spider.py", line 10, in parse
    print(response.body.encode('utf8'))
AttributeError: 'bytes' object has no attribute 'encode'
2017-02-17 12:28:07 [scrapy] ERROR: Spider error processing <GET https://www.atagar.com/echo.php> (referer: None)
Traceback (most recent call last):
  File "D:\Program Files\Anaconda3\envs\scrapy_test\lib\site-packages\twisted\internet\defer.py", line 651, in _runCallbacks
    current.result = callback(current.result, *args, **kw)
  File "C:\Users\djj\Desktop\upwork\ebook\ebook\spiders\proxy_test_spider.py", line 10, in parse
    print(response.body.encode('utf8'))
AttributeError: 'bytes' object has no attribute 'encode'
2017-02-17 12:29:59 [scrapy] ERROR: Spider error processing <GET http://ip.42.pl/raw> (referer: None)
Traceback (most recent call last):
  File "D:\Program Files\Anaconda3\envs\scrapy_test\lib\site-packages\twisted\internet\defer.py", line 651, in _runCallbacks
    current.result = callback(current.result, *args, **kw)
  File "C:\Users\djj\Desktop\upwork\ebook\ebook\spiders\proxy_test_spider.py", line 10, in parse
    print(response.text)
AttributeError: 'Response' object has no attribute 'text'
2017-02-17 12:29:59 [scrapy] ERROR: Spider error processing <GET https://www.atagar.com/echo.php> (referer: None)
Traceback (most recent call last):
  File "D:\Program Files\Anaconda3\envs\scrapy_test\lib\site-packages\twisted\internet\defer.py", line 651, in _runCallbacks
    current.result = callback(current.result, *args, **kw)
  File "C:\Users\djj\Desktop\upwork\ebook\ebook\spiders\proxy_test_spider.py", line 10, in parse
    print(response.text)
AttributeError: 'Response' object has no attribute 'text'
2017-02-17 12:30:06 [scrapy] ERROR: Spider error processing <GET http://ip.42.pl/raw> (referer: None)
Traceback (most recent call last):
  File "D:\Program Files\Anaconda3\envs\scrapy_test\lib\site-packages\twisted\internet\defer.py", line 651, in _runCallbacks
    current.result = callback(current.result, *args, **kw)
  File "C:\Users\djj\Desktop\upwork\ebook\ebook\spiders\proxy_test_spider.py", line 10, in parse
    print(response.text)
AttributeError: 'Response' object has no attribute 'text'
2017-02-17 12:30:06 [scrapy] ERROR: Spider error processing <GET https://www.atagar.com/echo.php> (referer: None)
Traceback (most recent call last):
  File "D:\Program Files\Anaconda3\envs\scrapy_test\lib\site-packages\twisted\internet\defer.py", line 651, in _runCallbacks
    current.result = callback(current.result, *args, **kw)
  File "C:\Users\djj\Desktop\upwork\ebook\ebook\spiders\proxy_test_spider.py", line 10, in parse
    print(response.text)
AttributeError: 'Response' object has no attribute 'text'
